Workbook

Sheet TEST_CASE
A1: Project Name | B1: SauceDemo Manual Testing
A2: Reference Document | B2: SWG-RA-2026, SWG-TP-2026, SWG-TS-2026
A3: Created By | B3: Nguyễn Long Vũ
A4: Date of creation | B4: 46175
A5: Date of reivew
A7: # | B7: Test Case ID | C7: Module | D7: Test Objective | E7: Type | F7: Priority | G7: Precondition | H7: Steps | I7: Test Data | J7: Expected Result | K7: Actual Result | L7: Status | M7: Bug ID | N7: Notes
A8: 1 | B8: TC_001 | C8: Login | D8: Successful login with standard_user | E8: Positive | F8: High | G8: 1.Browser is open 2. https://www.saucedemo.com/ is accessible | H8: 1.Navitage to https://www.saucedemo.com/ 2.Enter username in the Username field 3.Enter password in the Password field 4.Click the Login button | I8: standard_user secret_sauce | J8: User is authenticated Page redirects to /inventory.html within 3 seconds Inventory page loads with 6 products displayed | K8: Redirected to /inventory.html. 6 products displayed with images, names, prices. Load time approximately 1 second. | L8: PASS
A9: 2 | B9: TC_002 | C9: Login | D9: Redirect to /inventory.html after successful login | E9: Positive | F9: High | G9: 1.Browser is open 2. https://www.saucedemo.com/ is accessible | H9: 1.Login with standard_user / secret_sauce 2.Observe the URL after login completes | I9: standard_user secret_sauce | J9: URL changes to https://www.saucedemo.com/inventory.html Inventory page is fully rendered within 3 seconds | K9: URL changed to https://www.saucedemo.com/inventory.html. Inventory page fully rendered within 3 seconds. | L9: PASS
A10: 3 | B10: TC_003 | C10: Login | D10: Login fails with password incorrect | E10: Negative | F10: High | G10: 1.Browser is open 2. https://www.saucedemo.com/ is accessible | H10: 1.Enter a vaild username 2.Enter an incorrect password 3.Click Login | I10: standard_user wrong_password | J10: Error message is displayed : 'Username and password do not match any user in this service' User remains on the Login page No session is created | K10: Error message is displayed : 'Username and password do not match any user in this service' User remains on the Login page | L10: PASS
A11: 4 | B11: TC_004 | C11: Login | D11: Login fails when Username field is blank | E11: Negative | F11: High | G11: 1.Browser is open 2. https://www.saucedemo.com/ is accessible | H11: 1.Leave the Username field empty 2.Enter a vaild password 3.Click Login | I11: (Blank) secret_sauce | J11: Error message is displayed : 'Username is required' User remains on the Login page Password field is highlighted | K11: Error message is displayed : 'Username is required' User remains on the Login page | L11: PASS
A12: 5 | B12: TC_005 | C12: Login | D12: Login fails when Password field is blank | E12: Negative | F12: High | G12: 1.Browser is open 2. https://www.saucedemo.com/ is accessible | H12: 1.Enter a vaild Username 2.Leave the Password field empty 3.Click Login | I12: standard_user (Blank) | J12: Error message is displayed : 'Password is required' User remains on the Login page | K12: Error message is displayed : 'Password is required' User remains on the Login page | L12: PASS
A13: 6 | B13: TC_006 | C13: Login | D13: Login fails when Username fied and Password field is blank | E13: Negative | F13: High | G13: 1.Browser is open 2. https://www.saucedemo.com/ is accessible | H13: 1.Leave both Username and password fields empty 2.click Login | I13: (Blank) (Blank) | J13: Error message is displayed : 'Username is required' User remains on the Login page | K13: Error message is displayed : 'Username is required' User remains on the Login page | L13: PASS
A14: 7 | B14: TC_007 | C14: Login | D14: Locked account is rejected with clear message | E14: Negative | F14: High | G14: 1.Browser is open 2. https://www.saucedemo.com/ is accessible | H14: 1.Enter locked_out_user in Username 2.Enter secret_sauce in password | I14: locked_out_user secret_sauce | J14: Error displayed : "Sorry, this user has been locked out" User can not access application | K14: Error displayed : "Sorry, this user has been locked out" User can not access application | L14: PASS
A15: 8 | B15: TC_008 | C15: Login | D15: Error message is dismissible via X button | E15: Negative | F15: High | G15: 1.Browser is open 2. https://www.saucedemo.com/ is accessible | H15: 1.Trigger a login error (blank username ) 2.Verify error message content and position 3.Click the X button on the erorr message | I15: (blank username ) | J15: Step 2 : Error is visible with correct text at the top of the form Step 3 : Erorr message disappears , form returns to clean state | K15: Triggered login error with blank username. Step 2: Error message appeared at top of form with correct text and red border on input fields. Step 3: Clicked X button — error message disappeared. Red border removed. Form returned to clean state. | L15: PASS
A16: 9 | B16: TC_009 | C16: Login | D16: Password fied always masks input | E16: Positive | F16: High | G16: 1.Browser is open 2. https://www.saucedemo.com/ is accessible | H16: 1.Click on the Password field 2.Type any characters | I16: anyValue123 | J16: Characters are displayed as bullet dots(***) at all times Plaintext is never visible in the UI or page soucre | K16: Password characters displayed as bullet dots (•••) at all times. Plaintext not visible. | L16: PASS
A17: 10 | B17: TC_010 | C17: Login | D17: Login with problem_user succeeds , inventory shows intentional bugs | E17: Positive | F17: High | G17: 1.Browser is open 2. https://www.saucedemo.com/ is accessible | H17: 1.Enter problem_user in username 2.Enter secret_sauce in password 3.Click login 4.Observe the inventory page | I17: problem_user secret_sauce | J17: Login succeeds ; redireted to /inventory.html.Inventory page show intentional bugs(incorrect product image , ..) Document exact load time in test report | K17: Login successful Redirected to /inventory.html. Intentional bugs observed: all products show incorrect/same image. | L17: PASS
A18: 11 | B18: TC_011 | C18: Login | D18: Login with performace_glitch_user succeeds with delayed load | E18: Positive | F18: High | G18: 1.Browser is open 2. https://www.saucedemo.com/ is accessible | H18: 1.Enter performance_glitch_user in username 2.Enter secret_sauce in password 3.Click login 4.Record time until Inventory page is fully loaded | I18: performance_glitch_user secret_sauce | J18: Login succeeds, redirected to /inventory.html. Page load time exceeds 3 seconds (performance glitch behavior is expected for this account). Document actual load time in Notes. | K18: Login successful but page load took approximately 5 seconds. Slower than standard_user (1 second). | L18: PASS
A19: 12 | B19: TC_012 | C19: Login | D19: Unauthenticated direct URL access redirects to Login | E19: Negative | F19: High | G19: 1. No active session | H19: 1.Type https://www.saucedemo.com/inventory.html directly in browser address bar 2.Press Enter | J19: Application redirects to https://www.saucedemo.com/ Login page is displayed. Inventory is NOT accessible without authentication. | K19: Application redirected to https://www.saucedemo.com/inventory.html without login Page loaded successfully — NO redirect to login page. | L19: FAILS | M19: https://github.com/zues5sne/saucedemo-manual-testing/issues/2 | N19: Security issue — unauthenticated users can access protected pages directly via URL. Ref: NFR-S01 (Authentication Required)
A20: 13 | B20: TC_013 | C20: Login | D20: Login with special - character username shows appropriate | E20: Negative | F20: High | G20: 1.Browser is open 2. https://www.saucedemo.com/ is accessible | H20: 1.Enter username containing special characters or spaces 2.Enter any password 3.Click Login | I20: $$%$_username secret_sauce | J20: Error displayed :"Username and password do not match any user this service" User remains on Login page | K20: Error displayed :"Username and password do not match any user this service" User remains on Login page | L20: PASS
A21: 14 | B21: TC_014 | C21: Product List | D21: Inventory page displays exactly 6 products | E21: Positive | F21: Medium | G21: 1.User is logged in with standard_user/secret_sauce. 2.Application is on inventory page | H21: 1.Observe the inventory page after login 2.Count the total number of product cards displayed | J21: Exactly 6 product card are displayed No product are hidden or cut off | K21: Exactly 6 product cards are displayed on the inventory page. No products are hidden or cut off. All 6 products are fully visible without scrolling horizontally. | L21: PASS
A22: 15 | B22: TC_015 | C22: Product List | D22: Each product card show all 4 required components | E22: Positive | F22: Medium | G22: 1.User is logged in with standard_user/secret_sauce. 2.Application is on inventory page | H22: 1.Inspect each of the 6 product cards on inventory page 2.Verify presence of : image , name , description and price | I22: Check all 6 cards | J22: Every card contains : a product image , product name , product desciption , price lable , and "add to cart" button No missing fields on any card | K22: All 6 product cards show all required components: image, product name, description, price label and "Add to cart" button. No missing fields on any card. | L22: PASS
A23: 16 | B23: TC_016 | C23: Product List | D23: Sort by Name A-Z displays correct order | E23: Positive | F23: Medium | G23: 1.User is logged in with standard_user/secret_sauce. 2.Application is on inventory page | H23: 1.On the sort dropdown , select "Name (a-z)" 2.Observe the product order | I23: Sort option : Name (A-Z) | J23: Products displayed in order: Sauce Labs Backpack → Sauce Labs Bike Light → Sauce Labs Bolt T-Shirt → Sauce Labs Fleece Jacket → Sauce Labs Onesie → Test.allTheThings() T-Shirt. | K23: Products displayed in correct alphabetical order (A to Z): 1. Sauce Labs Backpack 2. Sauce Labs Bike Light 3. Sauce Labs Bolt T-Shirt 4. Sauce Labs Fleece Jacket 5. Sauce Labs Onesie 6. Test.allTheThings() T-Shirt (Red) | L23: PASS
A24: 17 | B24: TC_017 | C24: Product List | D24: Sort by Name Z-A displays correct order | E24: Positive | F24: Medium | G24: 1.User is logged in with standard_user/secret_sauce. 2.Application is on inventory page | H24: 1.On the sort dropdown , select "Name (Z-A)" 2.Observe the product order | I24: Sort option : Name (Z-A) | J24: "Products displayed in reverse alphabetical order (exact inverse of TC_016 result). First product: Test.allTheThings() T-Shirt. Last: Sauce Labs Backpack." | K24: Products displayed in reverse alphabetical order (Z to A): 1. Test.allTheThings() T-Shirt (Red) 2. Sauce Labs Onesie 3. Sauce Labs Fleece Jacket 4. Sauce Labs Bolt T-Shirt 5. Sauce Labs Bike Light 6. Sauce Labs Backpack | L24: PASS
A25: 18 | B25: TC_018 | C25: Product List | D25: Sort by Price : Low to High _ $7.99 appears first | E25: Positive | F25: Medium | G25: 1.User is logged in with standard_user/secret_sauce. 2.Application is on inventory page | H25: 1.Select 'Price (Low to High)' from the sort dropdown 2.Observe the product order and prices | I25: Sort option : Price (Low to High) | J25: "Products ordered: $7.99 → $9.99 → $15.99 → $15.99 → $29.99 → $49.99. Sauce Labs Onesie ($7.99) appears first. Sauce Labs Fleece Jacket ($49.99) appears last." | K25: Products sorted by price in ascending order: 1. Sauce Labs Onesie — $7.99 2. Sauce Labs Bike Light — $9.99 3. Sauce Labs Bolt T-Shirt — $15.99 4. Test.allTheThings() T-Shirt — $15.99 5. Sauce Labs Backpack — $29.99 6. Sauce Labs Fleece Jacket — $49.99 Cheapest product ($7.99) appears first as expected. | L25: PASS
A26: 19 | B26: TC_019 | C26: Product List | D26: Sort by Price : High to Low _ $49.99 appears first | E26: Positive | F26: Medium | G26: 1.User is logged in with standard_user/secret_sauce. 2.Application is on inventory page | H26: 1.Select 'Price (High to Low)' from the sort dropdown 2.Observe the product order and prices | I26: Sort option: Price (High to Low) | J26: "Products ordered: $49.99 → $29.99 → $15.99 → $15.99 → $9.99 → $7.99. Sauce Labs Fleece Jacket ($49.99) appears first." | K26: Products sorted by price in descending order: 1. Sauce Labs Fleece Jacket — $49.99 2. Sauce Labs Backpack — $29.99 3. Sauce Labs Bolt T-Shirt — $15.99 4. Test.allTheThings() T-Shirt — $15.99 5. Sauce Labs Bike Light — $9.99 6. Sauce Labs Onesie — $7.99 Most expensive product ($49.99) appears first as expected. | L26: PASS
A27: 20 | B27: TC_020 | C27: Product List | D27: Add to cart ' adds product ; button changes to "Remove" | E27: Positive | F27: Medium | G27: 1.User is logged in with standard_user/secret_sauce. 2.Application is on inventory page | H27: 1.Locate Sauce Labs BackPack on the inventory page 2.Click its"Adds to cart" button 3.Observe the button state and cart badge | J27: Button text changes from "add to cart " to "Remove" Cart badge in the header imcrements by 1 (Shows '1') | K27: Clicked "Add to cart" on Sauce Labs Backpack. Button label changed from "Add to cart" to "Remove" immediately. Cart badge appeared in header showing count "1". | L27: PASS
A28: 21 | B28: TC_021 | C28: Product List | D28: Remove ' remove product , button revert to 'Add to cart' | E28: Positive | F28: Medium | G28: 1.User is logged in with standard_user/secret_sauce. 2.Application is on inventory page | H28: 1.Locate Sauce Labs BackPack on the inventory page (button show Remove) 2.Click its"Remove" button 3.Observe the button state and cart badge | J28: Button text revert to "Add to cart" Cart badge in the header decrements by 1 .If cart is empty , badge disapears | K28: Clicked "Remove" on Sauce Labs Backpack. Button label reverted from "Remove" to "Add to cart". Cart badge count decreased by 1. If cart is empty, badge disappears from header. | L28: PASS
A29: 22 | B29: TC_022 | C29: Product List | D29: Cart badge count is accurate across multiple add/remove actions | E29: Positive | F29: Medium | G29: 1.User is logged in with standard_user/secret_sauce. 2.Application is on inventory page | H29: 1.Click "Add to cart " on 3 diferent products 2.Verify badge count 3.Click "Remove " on 1 product 4.Verify badge count again | I29: 3 product added Badge should show 3 1 product remove badge should show 2 | J29: Step 2 : Badge show "3" Step 3 : Badge show "2" Badge accturately reflects cart state at all times | K29: Added 3 products — badge shows "3". ✓ Removed 1 product — badge shows "2". ✓ Removed all products — badge disappears. ✓ Badge accurately reflects cart state at all times. | L29: PASS
A30: 23 | B30: TC_023 | C30: Product List | D30: (problem_user ) Product images display incorrectly (intentional bug) | E30: Negative | F30: Medium | G30: 1. Browser is open. 2. https://www.saucedemo.com is accessible. Account: problem_user / secret_sauce. | H30: 1.Login with problem_user 2.Observe all product images on inventory page 3.Document image mismatches | I30: problem_user | J30: "BUG EXPECTED: One or more product images do not match their product name. Document each mismatch: product name vs. actual image displayed." | K30: All 6 products displayed the same dog image. Product images do not match product names. Bug confirmed as expected. | L30: PASS
A31: 24 | B31: TC_024 | C31: Product List | D31: (problem_user) "Add to cart" fails for some product (intentional bug) | E31: Negative | F31: Medium | G31: 1. Browser is open. 2. https://www.saucedemo.com is accessible. Account: problem_user / secret_sauce. | H31: 1.Login with problem_user 2.Attempt to click "add to cart " on each of the 6 products 3.Observe button respone and badge for each | I31: problem_user | J31: BUG EXPECTED: At least one product's 'Add to cart' button does not respond or does not update the badge. Document which products are affected. | K31: Clicked "Add to cart" on multiple products. At least one product's "Add to cart" button did not respond when clicked. Badge count did not update for affected products. Bug confirmed as expected for problem_user account. | L31: PASS
A32: 25 | B32: TC_025 | C32: Product List | D32: (performance_glitch_user)Inventory page load exceeds 3 second threshold | E32: Negative | F32: Medium | G32: 1. Browser is open. 2. https://www.saucedemo.com is accessible. Account: performance_glitch_user / secret_sauce. | H32: 1.Login with performance_glitch_user 2.Start timer immediately after clicking Login 3.Stop timer when page inventory is fully rendered 4.Record load time | I32: performance_glitch_user | J32: "OBSERVED BUG: Inventory page load time exceeds 3 seconds (NFR-P01 threshold). Page eventually loads (within 8s per NFR-P06). Record exact load time in test report." | K32: Logged in with performance_glitch_user. Inventory page load time: approximately 5 seconds. Load time exceeds 3 seconds — slower than standard_user. Bug confirmed as expected. NFR-P01 threshold exceeded. | L32: PASS
A33: 26 | B33: TC_026 | C33: Product List | D33: Sortdown show all 4 options and retains selection | E33: Positive | F33: Medium | G33: 1. User is logged in with standard_user / secret_sauce. 2. Application is on Inventory page. | H33: 1. Click the Sort dropdown 2. Verify all 4 options are present 3. Select 'Price (high to low)' 4. Reload or navigate back and re-open dropdown | I33: 4 options: A-Z, Z-A, Low-High, High-Low | J33: Step 2: Dropdown contains exactly 4 options: Name (A to Z), Name (Z to A), Price (low to high), Price (high to low). Step 4: Selected sort option is retained within the session. | K33: Clicked Sort dropdown — 4 options displayed: Name (A to Z), Name (Z to A), Price (low to high), Price (high to low). Selected "Price (high to low)". Reloaded page — selected sort option was NOT retained (session reset). Dropdown reverts to default "Name (A to Z)" after reload. | L33: PASS
A34: 27 | B34: TC_027 | C34: Product Detail | D34: Click product name navigates to correct detail page | E34: Positive | F34: Medium | G34: 1.User is logged in with standard_user/secret_sauce. 2.Application is on inventory page | H34: 1.On inventory page , click the name of "Sauce Labs Backpack" 2.Observe the URL and page content | J34: "URL changes to /inventory-item.html?id=4 (or correct product ID). Detail page shows Sauce Labs Backpack information." | K34: Clicked on "Sauce Labs Backpack" product name. URL changed to /inventory-item.html?id=4 (correct product ID). Detail page shows Sauce Labs Backpack information. | L34: PASS
A35: 28 | B35: TC_028 | C35: Product Detail | D35: Click product images navigates to correct detail page | E35: Positive | F35: Medium | G35: 1.User is logged in with standard_user/secret_sauce. 2.Application is on inventory page | H35: 1.On inventory page , click the images of "Sauce Labs Backpack" 2.Observe the URL and page content | J35: "URL changes to /inventory-item.html?id=4 (or correct product ID). Detail page shows Sauce Labs Backpack information." | K35: Clicked on "Sauce Labs Backpack" product image. URL changed to /inventory-item.html?id=4 (correct product ID). Detail page shows Sauce Labs Backpack information. | L35: PASS
A36: 29 | B36: TC_029 | C36: Product Detail | D36: Product detail page displays all required elements | E36: Positive | F36: Medium | G36: 1.User is logged in with standard_user/secret_sauce. 2.Application is on inventory page | H36: 1.On inventory page , click on any product its open detail page 2.Verify all required elements are present on the page | I36: "Any product Check: image, name, description, price, Add to cart, Back button" | J36: All required elements are present: product image, product name, full description, price label, 'Add to cart' button, and 'Back to products' button. | K36: All required elements are present on detail page: product image, product name, full description, price label, "Add to cart" button and "Back to products" button. No missing fields detected. | L36: PASS
A37: 30 | B37: TC_030 | C37: Product Detail | D37: "Add to cart " on detail page adds iteam , badge increments | E37: Positive | F37: Medium | G37: 1.User is logged in with standard_user/secret_sauce. 2.Application is on inventory page 3.User is on a product detail page | H37: 1. Verify cart badge count before action 2. Click 'Add to cart' button on the Product Detail page 3. Observe button state and cart badge | I37: Initial badge count | J37: Button changes to 'Remove'. Cart badge increments by 1. Behavior is identical to adding from Inventory page. | K37: Clicked "Add to cart" on Product Detail page. Button changed to "Remove" immediately. Cart badge incremented by 1. Badge count is consistent with Inventory page. | L37: PASS
A38: 31 | B38: TC_031 | C38: Product Detail | D38: Button"Back to products " return user to inventory page | E38: Positive | F38: Medium | G38: 1.User is logged in with standard_user/secret_sauce. 2.Application is on inventory page 3.User is on a product detail page | H38: 1.Click "Back to product" button 2.Observe the resulting page and URL | J38: "URL returns to /inventory.html. Inventory page is displayed. Cart state (badge count and button states) is unchanged." | K38: Clicked "Back to products" button. URL returned to /inventory.html. Inventory page displayed correctly. Cart state (badge count and button states) is unchanged. | L38: PASS
A39: 32 | B39: TC_032 | C39: Product Detail | D39: Cart state preserved across Inventory → Detail → Back navigation | E39: Positive | F39: Medium | G39: 1. User is logged in with standard_user / secret_sauce. 2. Application is on Inventory page. 3. Sauce Labs Backpack has been added to Cart (badge = 1). | H39: 1. From Inventory, click Sauce Labs Bike Light to open detail page 2. Verify badge count on Detail page 3. Click 'Back to products' 4. Verify badge count on Inventory page | I39: Badge should show 1 Badge should show 1 | J39: Step 2: Badge shows '1' on Product Detail page. Step 4: Badge still shows '1' on Inventory page. Cart state is fully preserved across navigation. | K39: Added Sauce Labs Backpack to cart from Inventory. Badge shows "1". Navigated to Sauce Labs Bike Light detail page. Badge still shows "1". Clicked "Back to products". Badge still shows "1". Cart state is fully preserved across navigation. | L39: PASS
A40: 33 | B40: TC_033 | C40: Product Detail | D40: [problem_user] Detail page shows incorrect product info (intentional bug) | E40: Negative | F40: Medium | G40: 1. Browser is open. 2. https://www.saucedemo.com is accessible. Account: problem_user / secret_sauce. | H40: 1. Login with problem_user 2. Click on 'Sauce Labs Backpack' to open detail page 3. Compare name, image, and description on detail vs. inventory page | I40: problem_user | J40: BUG EXPECTED: Product information on Detail page (image, name, or description) does not match the product selected on Inventory page. Document exact mismatch. | K40: BUG EXPECTED: Product information on Detail page (image, name, or description) does not match the product selected on Inventory page. Exact mismatch documented. | L40: PASS
A41: 34 | B41: TC_034 | C41: Product Detail | D41: URL contains correct product ID for each product | E41: Positive | F41: Medium | G41: 1. User is logged in with standard_user / secret_sauce. 2. Application is on Inventory page. | H41: 1. Click on 'Sauce Labs Backpack' from Inventory; check URL 2. Go back; click on 'Sauce Labs Bike Light'; check URL 3. Repeat for all 6 products | I41: Check all 6 | J41: Each product opens a unique URL with a distinct product ID (e.g. ?id=4, ?id=0, etc.). No two products share the same URL. URL is stable and bookmarkable. | K41: Each product opens a unique URL with distinct product ID: - Sauce Labs Backpack → ?id=4 - Sauce Labs Bike Light → ?id=0 No two products share the same URL. URL is stable and bookmarkable. | L41: PASS
...

Sheet TEST_SUMMARY_REPORT
A1: TEST SUMMARY REPORT — SWAG LABS (saucedemo.com)
A3: PROJECT INFORMATION
B4: Project | C4: SauceDemo Manual Testing
B5: Website | C5: https://www.saucedemo.com
B6: Tester | C6: Nguyễn Long Vũ
B7: Test Period | C7: 02/06/2026 — 09/06/2026
B8: Environment | C8: Chrome 124 / Windows 11 / 1920×1080
B9: Reference | C9: SWG-RA-2026 | SWG-TP-2026 | SWG-TS-2026
B10: Report Date
A12: OVERALL TEST RESULTS
B13: Total TC | C13: Pass | D13: Fail | E13: Skip | F13: Pass Rate | G13: Overall
B14: =COUNTA(TEST_CASE!B8:B73) -> 66 | C14: =COUNTIF(TEST_CASE!L8:L73, "PASS") -> 65 | D14: =COUNTIF(TEST_CASE!L8:L73, "FAILS") -> 1 | E14: =COUNTIF(TEST_CASE!L8:L73, "SKIP") -> 0 | F14: =C14/B14 -> 0.98484848
B16: Module | C16: Total TC | D16: Pass | E16: Fail | F16: Pass Rate | G16: Notes
B17: Login | C17: =COUNTIF(TEST_CASE!C8:C73, "Login") -> 13 | D17: =COUNTIFS(TEST_CASE!C8:C73, "Login", TEST_CASE!L8:L73, "PASS") -> 12 | E17: =COUNTIFS(TEST_CASE!C8:C73, "Login", TEST_CASE!L8:L73, "FAILS") -> 1 | F17: =D17/C17 -> 0.92307692 | G17: 1 security bug (BUG-001)
B18: Product List | C18: =COUNTIF(TEST_CASE!C9:C74, "Product List") -> 13 | D18: =COUNTIFS(TEST_CASE!C9:C74, "Product List", TEST_CASE!L9:L74, "PASS") -> 13 | E18: =COUNTIFS(TEST_CASE!C9:C74, "Product List", TEST_CASE!L9:L74, "FAILS") -> 0 | F18: =D18/C18 -> 1 | G18: All pass — intentional bugs documented
B19: Product Detail | C19: =COUNTIF(TEST_CASE!C10:C75, "Product Detail") -> 8 | D19: =COUNTIFS(TEST_CASE!C10:C75, "Product Detail", TEST_CASE!L10:L75, "PASS") -> 8 | E19: =COUNTIFS(TEST_CASE!C10:C75, "Product Detail", TEST_CASE!L10:L75, "FAILS") -> 0 | F19: =D19/C19 -> 1 | G19: Navigation & cart state consistent
B20: Shopping Cart | C20: =COUNTIF(TEST_CASE!C11:C76, "Cart") -> 10 | D20: =COUNTIFS(TEST_CASE!C11:C76, "Cart", TEST_CASE!L11:L76, "PASS") -> 10 | E20: =COUNTIFS(TEST_CASE!C11:C76, "Cart", TEST_CASE!L11:L76, "FAILS") -> 0 | F20: =D20/C20 -> 1 | G20: Cart state management works correctly
B21: Checkout | C21: =COUNTIF(TEST_CASE!C12:C77, "Checkout") -> 16 | D21: =COUNTIFS(TEST_CASE!C12:C77, "Checkout", TEST_CASE!L12:L77, "PASS") -> 16 | E21: =COUNTIFS(TEST_CASE!C12:C77, "Checkout", TEST_CASE!L12:L77, "FAILS") -> 0 | F21: =D21/C21 -> 1 | G21: E2E flow complete. Pricing correct.
B22: Logout & Nav | C22: =COUNTIF(TEST_CASE!C13:C78, "Logout & Nav") -> 6 | D22: =COUNTIFS(TEST_CASE!C13:C78, "Logout & Nav", TEST_CASE!L13:L78, "PASS") -> 6 | E22: =COUNTIFS(TEST_CASE!C13:C78, "Logout & Nav", TEST_CASE!L13:L78, "FAILS") -> 0 | F22: =D22/C22 -> 1 | G22: Session invalidated on logout
B23: TOTAL | C23: =SUM(C17:C22) -> 66 | D23: =SUM(D17:D22) -> 65 | E23: =SUM(E17:E22) -> 1 | F23: =D23/C23 -> 0.98484848
A25: BUG REPORT SUMMARY
B26: Bug ID | C26: Module | D26: Severity | E26: Status | F26: TC Ref | G26: Title
B27: BUG-001 | C27: Login / Security | D27: High | E27: Open | F27: TC_012 | G27: Unauthenticated user can access /inventory.html without login
A29: PERSONAL NOTES & OBSERVATIONS (Tester's own words)
B30: Note 1: TC_012 — Bug discovery | C30: Lần đầu test TC_012, tôi tưởng mình làm sai bước nên test lại 2 lần trước khi chắc chắn đây là bug thật. Hệ thống không redirect về Login khi truy cập URL trực tiếp — đây là lỗi bảo mật nghiêm trọng (NFR-S01).
B31: Note 2: TC_050 — Expected Result sai | C31: Ban đầu tôi viết Expected Result của TC_050 là về /inventory.html. Khi test thật thì thấy Cancel ở Step 1 về /cart.html. Đây là behavior hợp lý hơn về UX — tôi đã sửa lại Expected Result thay vì log bug.
B32: Note 3: TC_043 — problem_user Cart | C32: Tôi tưởng Cart của problem_user sẽ bị lỗi. Nhưng test thật thì hoạt động bình thường. Bug của problem_user chỉ nằm ở Inventory (ảnh sai) và Product Detail — không phải Cart. Bài học: không assume, phải test thật.
B33: Note 4: TC_058 — error_user | C33: Phát hiện 3 bug của error_user: (1) Last Name field redirect input sang Zip field, (2) form vẫn submit dù Last Name trống, (3) Finish button không hoạt động ở Step 2. Tất cả là intentional bugs — không log GitHub Issue.
B34: Note 5: TC_060 — Pricing formula | C34: Đã verify công thức tính tiền với 3 tổ hợp sản phẩm khác nhau. Tax = 8% × Item Total, làm tròn 2 chữ số thập phân. Tất cả kết quả đúng 100%. Đây là chức năng quan trọng nhất của Checkout.
A36: CONCLUSION & RECOMMENDATION
B37: Overall | C37: 98.5% pass rate (65/66 TC). Core E2E Happy Path works correctly end-to-end.
B38: Must Fix | C38: BUG-001: Implement authentication check — unauthenticated URL access must redirect to Login.
B39: Known Issues | C39: Intentional bugs in problem_user, error_user, visual_user accounts — by design, no fix needed.
B40: Recommendation | C40: CONDITIONALLY APPROVED for standard_user flow after BUG-001 is fixed.
